Run `repro.sh` to reproduce the crash. It works for me on x86-64 Arch Linux and PyPy 7.3.5.

Upstream issue: https://github.com/PyO3/pyo3/issues/1736
